Workbook

Sheet Pump Change Risk
A1: Pump Change Risk Analysis — 16-18 Month Average Pump Life
A2: HIGH = running 12+ mo (due/overdue) | RECENTLY CHANGED = shutdown + restart in 2025 | DOWN NOW = not producing Dec 2025
A3: HIGH — DUE: 199 wells | WATCH: 11 wells | RECENTLY CHANGED: 14 wells | LOW: 31 wells | DOWN NOW: 30 wells
A5: Risk Level | B5: Well Identifier | C5: Facility Name | D5: Location | E5: Consec. Months Running | F5: Dec 2025 bbl/d | G5: 2025 Total bbl | H5: Prod Hours | I5: Shutdown Months | J5: Restart Months | K5: Status Note
A6: HIGH — DUE | B6: 100082908218W509 | C6: OBE HVS 08-28-082-18W5 | D6: 08-28-082-18W5 | E6: 12 | F6: 137.3 | G6: 75407 | H6: 8704 | K6: Running 12+ months (no shutdown in 2025) — likely at or past pump change window
A7: HIGH — DUE | B7: 102081807916W509 | C7: OBE PEAVINE 08-13-079-17W5 | D7: 13-079-17W5 | E7: 12 | F7: 118.6 | G7: 65335 | H7: 8753 | K7: Running 12+ months (no shutdown in 2025) — likely at or past pump change window
A8: HIGH — DUE | B8: 100141708317W509 | C8: OBE HVS 13-08-083-17W5 | D8: 13-08-083-17W5 | E8: 12 | F8: 158.3 | G8: 65082 | H8: 8530 | K8: Running 12+ months (no shutdown in 2025) — likely at or past pump change window
A9: HIGH — DUE | B9: 100151908317W509 | C9: OBE HVS 13-18-083-17W5 | D9: 13-18-083-17W5 | E9: 12 | F9: 113.8 | G9: 62143 | H9: 8553 | K9: Running 12+ months (no shutdown in 2025) — likely at or past pump change window
A10: HIGH — DUE | B10: 102041207917W508 | C10: OBE DAWSON 13-13-079-17W5 | D10: 13-13-079-17W5 | E10: 12 | F10: 109.4 | G10: 60920 | H10: 8682 | K10: Running 12+ months (no shutdown in 2025) — likely at or past pump change window
A11: HIGH — DUE | B11: 100051907916W509 | C11: OBE PEAVINE 08-13-079-17W5 | D11: 13-079-17W5 | E11: 12 | F11: 89.9 | G11: 55442 | H11: 8706 | K11: Running 12+ months (no shutdown in 2025) — likely at or past pump change window
A12: HIGH — DUE | B12: 100043208319W509 | C12: OBE CADOTTE 02-05-084-19W5 | D12: 05-084-19W5 | E12: 12 | F12: 115 | G12: 52271 | H12: 8064 | K12: Running 12+ months (no shutdown in 2025) — likely at or past pump change window
A13: HIGH — DUE | B13: 102011207917W509 | C13: OBE DAWSON 07-13-079-17W5 | D13: 13-079-17W5 | E13: 12 | F13: 60 | G13: 50927 | H13: 8500 | K13: Running 12+ months (no shutdown in 2025) — likely at or past pump change window
A14: HIGH — DUE | B14: 102143008216W509 | C14: OBE WALRUS 13-19-082-16W5 | D14: 19-082-16W5 | E14: 12 | F14: 126.3 | G14: 49412 | H14: 8656 | K14: Running 12+ months (no shutdown in 2025) — likely at or past pump change window
A15: HIGH — DUE | B15: 103012708218W509 | C15: OBE HVS 08-28-082-18W5 | D15: 08-28-082-18W5 | E15: 12 | F15: 64.4 | G15: 48127 | H15: 8685 | K15: Running 12+ months (no shutdown in 2025) — likely at or past pump change window
A16: HIGH — DUE | B16: 102082708218W509 | C16: OBE HVS 08-28-082-18W5 | D16: 08-28-082-18W5 | E16: 12 | F16: 65.7 | G16: 45754 | H16: 8667 | K16: Running 12+ months (no shutdown in 2025) — likely at or past pump change window
A17: HIGH — DUE | B17: 100081807916W509 | C17: OBE PEAVINE 08-13-079-17W5 | D17: 13-079-17W5 | E17: 12 | F17: 88.4 | G17: 45287 | H17: 8736 | K17: Running 12+ months (no shutdown in 2025) — likely at or past pump change window
... A204: HIGH — DUE | B204: 104090808215W500 | C204: OBE SEAL 13-08-082-15W5 | D204: 13-08-082-15W5 | E204: 12 | F204: 5.6 | G204: 1475 | H204: 8624 | K204: Running 12+ months (no shutdown in 2025) — likely at or past pump change window
A205: WATCH | B205: 100062207917W509 | C205: OBE DAWSON 04-23-079-17W5 | D205: 04-23-079-17W5 | E205: 10 | F205: 106.9 | G205: 52366 | H205: 6842 | J205: Mar | K205: Running 10 months — approaching window
A206: WATCH | B206: 102041108114W509 | C206: OBE SEAL 04-14-081-14W5 MWB | D206: 04-14-081-14W5 | E206: 10 | F206: 164 | G206: 50727 | H206: 7137 | J206: Mar | K206: Running 10 months — approaching window
A207: WATCH | B207: 102082107917W509 | C207: OBE DAWSON 04-23-079-17W5 | D207: 04-23-079-17W5 | E207: 10 | F207: 85.5 | G207: 34449 | H207: 7004 | J207: Mar | K207: Running 10 months — approaching window
A208: WATCH | B208: 103090508415W509 | C208: OBE NAMPA 09-06-084-15W5 | D208: 09-06-084-15W5 | E208: 10 | F208: 38.3 | G208: 15774 | H208: 6861 | J208: Mar | K208: Running 10 months — approaching window
A209: WATCH | B209: 1W0120408415W509 | C209: OBE NAMPA 09-06-084-15W5 | D209: 09-06-084-15W5 | E209: 10 | F209: 27.8 | G209: 11236 | H209: 6880 | J209: Mar | K209: Running 10 months — approaching window
A210: WATCH | B210: 102060108216W503 | C210: Pennwest Seal | D210: 13-06-082-15W5 | E210: 11 | F210: 30.4 | G210: 10510 | H210: 7716 | J210: Feb | K210: Running 11 months — approaching window
A211: WATCH | B211: 100042807916W500 | C211: OBE PEAVINE 13-16-079-16W5 | D211: 13-16-079-16W5 | E211: 11 | F211: 23.3 | G211: 7501 | H211: 8124 | J211: Feb | K211: Running 11 months — approaching window
A212: WATCH | B212: 100163408318W509 | C212: OBE CADOTTE 14-27-083-18W5 | D212: 14-27-083-18W5 | E212: 11 | F212: 7.7 | G212: 5907 | H212: 8065 | J212: Feb | K212: Running 11 months — approaching window
A213: WATCH | B213: 100160508317W509 | C213: OBE HVS 15-06-083-17W5 | D213: 15-06-083-17W5 | E213: 11 | F213: 14.6 | G213: 5246 | H213: 7232 | J213: Feb | K213: Running 11 months — approaching window
A214: WATCH | B214: 100092908318W509 | C214: OBE CADOTTE 13-27-083-18W5 | D214: 13-27-083-18W5 | E214: 11 | F214: 9.2 | G214: 4779 | H214: 8061 | J214: Feb | K214: Running 11 months — approaching window
A215: WATCH | B215: 102032308419W509 | C215: OBE CADOTTE 15-14-084-19W5 | D215: 15-14-084-19W5 | E215: 11 | F215: 7.2 | G215: 2974 | H215: 7756 | J215: Feb | K215: Running 11 months — approaching window
A216: RECENTLY CHANGED | B216: 100021908317W509 | C216: OBE HVS 14-07-083-17W5 MWB | D216: 14-07-083-17W5 | E216: 5 | F216: 272 | G216: 78009 | H216: 5034 | I216: Jul | J216: May, Aug | K216: Likely pump change around Aug — running 5 months since
A217: RECENTLY CHANGED | B217: 102162107917W509 | C217: OBE DAWSON 13-23-079-17W5 MWB | D217: 13-23-079-17W5 | E217: 5 | F217: 69.1 | G217: 25688 | H217: 7949 | I217: Jul | J217: Aug | K217: Likely pump change around Aug — running 5 months since
A218: RECENTLY CHANGED | B218: 100012807917W508 | C218: OBE DAWSON 13-23-079-17W5 MWB | D218: 13-23-079-17W5 | E218: 5 | F218: 85.4 | G218: 24820 | H218: 7578 | I218: Jul | J218: Aug | K218: Likely pump change around Aug — running 5 months since
A219: RECENTLY CHANGED | B219: 100021608216W509 | C219: OBE WALRUS 07-21-082-16W5 | D219: 07-21-082-16W5 | E219: 9 | F219: 62.4 | G219: 16823 | H219: 6640 | I219: Feb | J219: Apr | K219: Likely pump change around Apr — running 9 months since
A220: RECENTLY CHANGED | B220: 100032207917W509 | C220: OBE DAWSON 04-23-079-17W5 | D220: 04-23-079-17W5 | E220: 3 | F220: 79.4 | G220: 12477 | H220: 4124 | I220: Aug | J220: Apr, Oct | K220: Likely pump change around Oct — running 3 months since
A221: RECENTLY CHANGED | B221: 100043507917W509 | C221: OBE DAWSON 13-23-079-17W5 MWB | D221: 13-23-079-17W5 | E221: 5 | F221: 29.1 | G221: 12022 | H221: 7962 | I221: Jul | J221: Aug | K221: Likely pump change around Aug — running 5 months since
A222: RECENTLY CHANGED | B222: 100013508516W509 | C222: OBE NAMPA 07-34-085-16W5 | D222: 34-085-16W5 | E222: 2 | F222: 113.7 | G222: 11114 | H222: 2187 | I222: Apr | J222: Feb, Nov | K222: Likely pump change around Nov — running 2 months since
A223: RECENTLY CHANGED | B223: 100151208317W509 | C223: OBE WALRUS 15-01-083-17W5 | D223: 01-083-17W5 | E223: 3 | F223: 5.2 | G223: 4461 | H223: 5085 | I223: Jul | J223: Oct | K223: Likely pump change around Oct — running 3 months since
A224: RECENTLY CHANGED | B224: 103143008318W509 | C224: OBE CADOTTE 03-30-083-18W5 | D224: 03-30-083-18W5 | E224: 7 | F224: 1.3 | G224: 3717 | H224: 6767 | I224: Apr | J224: Jun | K224: Likely pump change around Jun — running 7 months since
A225: RECENTLY CHANGED | B225: 100013308218W509 | C225: OBE HVS 16-27-082-18W5 | D225: 16-27-082-18W5 | E225: 7 | F225: 12.7 | G225: 3492 | H225: 7374 | I225: May | J225: Jun | K225: Likely pump change around Jun — running 7 months since
A226: RECENTLY CHANGED | B226: 102043208318W509 | C226: OBE CADOTTE 04-29-083-18W5 | D226: 04-29-083-18W5 | E226: 6 | F226: 10.2 | G226: 3249 | H226: 6681 | I226: May | J226: Jul | K226: Likely pump change around Jul — running 6 months since
A227: RECENTLY CHANGED | B227: 100153108217W509 | C227: OBE HVS 02-05-082-17W5 | D227: 01-05-083-17W5 | E227: 9 | F227: 2.7 | G227: 3047 | H227: 7060 | I227: Mar | J227: Feb, Apr | K227: Likely pump change around Apr — running 9 months since
...

Sheet Downtime Analysis
A1: Pump Change / Downtime Flagging — Peace River 2025
A2: Monthly uptime % per well | RED = <50% uptime | YELLOW = 50-80% | GREEN = >80% | Blank = not producing that month
A4: Well Identifier | B4: Facility | C4: Total Downtime (days) | D4: Annual Uptime % | E4: Jan | F4: Feb | G4: Mar | H4: Apr | I4: May | J4: Jun | K4: Jul | L4: Aug | M4: Sep | N4: Oct | O4: Nov | P4: Dec | Q4: Flag
A5: 100162608218W502 | B5: OBE HVS 09-25-082-18W5 | C5: 364 | D5: 0.002739726 | E5: 0.032258065 | F5: DOWN | G5: DOWN | H5: DOWN | I5: DOWN | J5: DOWN | K5: DOWN | L5: DOWN | M5: DOWN | N5: DOWN | O5: DOWN | P5: DOWN | Q5: FULL SHUTDOWN
A6: 100093108319W509 | B6: OBE CADOTTE 09-36-083-19W5 | C6: 361.1 | D6: 0.010616438 | E6: 0.125 | F6: DOWN | G6: DOWN | H6: DOWN | I6: DOWN | J6: DOWN | K6: DOWN | L6: DOWN | M6: DOWN | N6: DOWN | O6: DOWN | P6: DOWN | Q6: FULL SHUTDOWN
A7: 102020108318W508 | B7: OBE HVS 15-01-083-18W5 | C7: 356.5 | D7: 0.023287671 | E7: 0.27419355 | F7: DOWN | G7: DOWN | H7: DOWN | I7: DOWN | J7: DOWN | K7: DOWN | L7: DOWN | M7: DOWN | N7: DOWN | O7: DOWN | P7: DOWN | Q7: FULL SHUTDOWN
A8: 100040108318W509 | B8: OBE HVS 15-01-083-18W5 | C8: 356.5 | D8: 0.023287671 | E8: 0.27419355 | F8: DOWN | G8: DOWN | H8: DOWN | I8: DOWN | J8: DOWN | K8: DOWN | L8: DOWN | M8: DOWN | N8: DOWN | O8: DOWN | P8: DOWN | Q8: FULL SHUTDOWN
A9: 100020108318W502 | B9: OBE HVS 15-01-083-18W5 | C9: 356 | D9: 0.024657534 | E9: 0.29032258 | F9: DOWN | G9: DOWN | H9: DOWN | I9: DOWN | J9: DOWN | K9: DOWN | L9: DOWN | M9: DOWN | N9: DOWN | O9: DOWN | P9: DOWN | Q9: FULL SHUTDOWN
A10: 100163008216W509 | B10: OBE WALRUS 15-19-082-16W5 | C10: 355 | D10: 0.02739726 | E10: 0.32258065 | F10: DOWN | G10: DOWN | H10: DOWN | I10: DOWN | J10: DOWN | K10: DOWN | L10: DOWN | M10: DOWN | N10: DOWN | O10: DOWN | P10: DOWN | Q10: FULL SHUTDOWN
A11: 102162108419W509 | B11: OBE CADOTTE 13-15-084-19W5 | C11: 337.7 | D11: 0.074885845 | E11: 0.052419355 | F11: 0.91815476 | G11: DOWN | H11: DOWN | I11: DOWN | J11: DOWN | K11: DOWN | L11: DOWN | M11: DOWN | N11: DOWN | O11: DOWN | P11: DOWN | Q11: FULL SHUTDOWN
A12: 100103108319W509 | B12: OBE CADOTTE 09-36-083-19W5 | C12: 327.3 | D12: 0.018378995 | F12: 0.23363095 | G12: 0.0053763441 | H12: DOWN | I12: DOWN | J12: DOWN | K12: DOWN | L12: DOWN | M12: DOWN | N12: DOWN | O12: DOWN | P12: DOWN | Q12: FULL SHUTDOWN
A13: 102132208419W509 | B13: OBE CADOTTE 13-15-084-19W5 | C13: 324.5 | D13: 0.11084475 | E13: 0.94086022 | F13: 0.40327381 | G13: DOWN | H13: DOWN | I13: DOWN | J13: DOWN | K13: DOWN | L13: DOWN | M13: DOWN | N13: DOWN | O13: DOWN | P13: DOWN | Q13: FULL SHUTDOWN
A14: 100152608117W508 | B14: OBE HVS 10-27-081-17W5 | C14: 306.8 | D14: 0.074543379 | F14: 0.32142857 | G14: 0.58736559 | H14: DOWN | I14: DOWN | J14: DOWN | K14: DOWN | L14: DOWN | M14: DOWN | N14: DOWN | O14: DOWN | P14: DOWN | Q14: FULL SHUTDOWN
A15: 100083108319W509 | B15: OBE CADOTTE 09-36-083-19W5 | C15: 300.8 | D15: 0.09086758 | F15: 0.85267857 | G15: 0.29973118 | H15: DOWN | I15: DOWN | J15: DOWN | K15: DOWN | L15: DOWN | M15: DOWN | N15: DOWN | O15: DOWN | P15: DOWN | Q15: FULL SHUTDOWN
A16: 100101508013W500 | B16: OBE GIFT LAKE 15-22-080-13W5 | C16: 298.5 | D16: 0.097260274 | F16: 0.76785714 | G16: 0.4516129 | H16: DOWN | I16: DOWN | J16: DOWN | K16: DOWN | L16: DOWN | M16: DOWN | N16: DOWN | O16: DOWN | P16: DOWN | Q16: FULL SHUTDOWN
A17: 100121507815W500 | B17: OBE PEAVINE 11-14-078-15W5 | C17: 297.9 | D17: 0.022146119 | G17: 0.26075269 | H17: DOWN | I17: DOWN | J17: DOWN | K17: DOWN | L17: DOWN | M17: DOWN | N17: DOWN | O17: DOWN | P17: DOWN | Q17: FULL SHUTDOWN
A18: 100081408117W509 | B18: OBE HVS 15-15-081-17W5 | C18: 294.9 | D18: 0.10707763 | F18: 0.6577381 | G18: 0.66666667 | H18: DOWN | I18: DOWN | J18: DOWN | K18: DOWN | L18: DOWN | M18: DOWN | N18: DOWN | O18: DOWN | P18: DOWN | Q18: FULL SHUTDOWN
A19: 100161208317W509 | B19: OBE WALRUS 15-01-083-17W5 | C19: 291 | D19: 0.11769406 | F19: 0.88541667 | G19: 0.58602151 | H19: DOWN | I19: DOWN | J19: DOWN | K19: DOWN | L19: DOWN | M19: DOWN | N19: DOWN | O19: DOWN | P19: DOWN | Q19: FULL SHUTDOWN
A20: 100052908516W509 | B20: OBE NAMPA 06-28-085-16W5 | C20: 283.6 | D20: 0.22305936 | E20: 1 | F20: 1 | G20: 0.72311828 | H20: DOWN | I20: DOWN | J20: DOWN | K20: DOWN | L20: DOWN | M20: DOWN | N20: DOWN | O20: DOWN | P20: DOWN | Q20: FULL SHUTDOWN
A21: 100161808516W509 | B21: OBE NAMPA 13-08-085-16W5 | C21: 278.2 | D21: 0.076141553 | G21: 0.64516129 | H21: DOWN | I21: DOWN | J21: DOWN | K21: DOWN | L21: DOWN | M21: DOWN | N21: DOWN | O21: DOWN | P21: 0.25134409 | Q21: FULL SHUTDOWN
A22: 100080508215W500 | B22: OBE SEAL 13-08-082-15W5 | C22: 268 | D22: 0.26586758 | E22: 0.93817204 | F22: 0.94642857 | G22: 0.98655914 | H22: 0.3625 | I22: DOWN | J22: DOWN | K22: DOWN | L22: DOWN | M22: DOWN | N22: DOWN | O22: DOWN | P22: DOWN | Q22: FULL SHUTDOWN
A23: 100013508516W509 | B23: OBE NAMPA 07-34-085-16W5 | C23: 242.9 | D23: 0.24965753 | F23: 0.92708333 | G23: 0.71639785 | H23: DOWN | I23: DOWN | J23: DOWN | K23: DOWN | L23: DOWN | M23: DOWN | N23: DOWN | O23: 0.4 | P23: 0.99865591 | Q23: FULL SHUTDOWN
A24: 100060307722W502 | B24: N7 GIROUXVILLE 06-03/2 SWB | C24: 217 | D24: 0.076712329 | I24: 0.90322581 | J24: DOWN | K24: DOWN | L24: DOWN | M24: DOWN | N24: DOWN | O24: DOWN | P24: DOWN | Q24: FULL SHUTDOWN
A25: 103052307917W500 | B25: OBE DAWSON 04-24-079-17W5 | C25: 176 | D25: 0.1890411 | I25: 0.35483871 | J25: 1 | K25: 0.90322581 | L25: DOWN | M25: DOWN | N25: DOWN | O25: DOWN | P25: DOWN | Q25: FULL SHUTDOWN
A26: 103012207917W500 | B26: OBE DAWSON 04-24-079-17W5 | C26: 173.7 | D26: 0.19543379 | I26: 0.43010753 | J26: 1 | K26: 0.90322581 | L26: DOWN | M26: DOWN | N26: DOWN | O26: DOWN | P26: DOWN | Q26: FULL SHUTDOWN
A27: 100162408419W500 | B27: OBE CADOTTE 16-13-084-19W5 | C27: 164 | D27: 0.55068493 | E27: 1 | F27: 1 | G27: 1 | H27: 1 | I27: 1 | J27: 1 | K27: 0.64516129 | L27: DOWN | M27: DOWN | N27: DOWN | O27: DOWN | P27: DOWN | Q27: FULL SHUTDOWN
A28: 100151208317W509 | B28: OBE WALRUS 15-01-083-17W5 | C28: 153.1 | D28: 0.58047945 | E28: 0.32258065 | F28: 0.63690476 | G28: 0.99462366 | H28: 0.79166667 | I28: 0.9516129 | J28: 0.37083333 | K28: DOWN | L28: DOWN | M28: DOWN | N28: 0.89784946 | O28: 1 | P28: 1 | Q28: FULL SHUTDOWN
A29: 100160808218W509 | B29: OBE HVS 16-09-082-18W5 | C29: 133.5 | D29: 0.38767123 | H29: 0.97361111 | I29: 0.82526882 | J29: DOWN | K29: DOWN | L29: 0.98521505 | M29: 1 | N29: 0.84408602 | O29: DOWN | P29: DOWN | Q29: FULL SHUTDOWN
A30: 100011608114W509 | B30: OBE SEAL 04-14-081-14W5 MWB | C30: 109 | D30: 0.28767123 | J30: 0.96388889 | K30: 0.98924731 | L30: 0.93817204 | M30: 0.54444444 | N30: DOWN | O30: DOWN | P30: DOWN | Q30: FULL SHUTDOWN
A31: 100032207917W509 | B31: OBE DAWSON 04-23-079-17W5 | C31: 103.2 | D31: 0.47077626 | H31: 0.38888889 | I31: 0.91397849 | J31: 0.96666667 | K31: 0.41935484 | L31: DOWN | M31: DOWN | N31: 0.93010753 | O31: 1 | P31: 1 | Q31: FULL SHUTDOWN
A32: 100021608216W509 | B32: OBE WALRUS 07-21-082-16W5 | C32: 88.3 | D32: 0.75799087 | E32: 0.84005376 | F32: DOWN | G32: DOWN | H32: 0.3875 | I32: 0.81317204 | J32: 1 | K32: 1 | L32: 1 | M32: 1 | N32: 1 | O32: 1 | P32: 0.99327957 | Q32: FULL SHUTDOWN
A33: 102043208318W509 | B33: OBE CADOTTE 04-29-083-18W5 | C33: 86.6 | D33: 0.76267123 | E33: 1 | F33: 1 | G33: 1 | H33: 0.775 | I33: DOWN | J33: DOWN | K33: 0.41935484 | L33: 0.99193548 | M33: 1 | N33: 1 | O33: 1 | P33: 0.97983871 | Q33: FULL SHUTDOWN
A34: 102153108217W509 | B34: OBE HVS 14-05-083-17W5 | C34: 83.5 | D34: 0.77134703 | E34: 1 | F34: 0.86160714 | G34: 0.80376344 | H34: 0.58194444 | I34: 0.63306452 | J34: 0.5625 | K34: 0.37903226 | L34: 0.44489247 | M34: 1 | N34: 1 | O34: 1 | P34: 1 | Q34: MAJOR DOWNTIME
A35: 103143008318W509 | B35: OBE CADOTTE 03-30-083-18W5 | C35: 83 | D35: 0.77248858 | E35: 1 | F35: 0.96428571 | G35: 0.60215054 | H35: 0.11944444 | I35: 0.13172043 | J35: 0.55416667 | K35: 1 | L35: 0.93548387 | M35: 1 | N35: 1 | O35: 1 | P35: 0.96774194 | Q35: MAJOR DOWNTIME
A36: 104152408419W500 | B36: OBE CADOTTE 16-13-084-19W5 | C36: 77 | D36: 0.7890411 | E36: 1 | F36: 1 | G36: 1 | H36: 1 | I36: 1 | J36: 0.8 | K36: 0.70967742 | L36: 1 | M36: 1 | N36: 0.96774194 | O36: DOWN | P36: DOWN | Q36: FULL SHUTDOWN
A37: 100140808317W509 | B37: OBE HVS 14-05-083-17W5 | C37: 72.5 | D37: 0.80125571 | E37: 1 | F37: 0.75892857 | G37: 0.79569892 | H37: 0.39305556 | I37: 0.56451613 | J37: 0.73472222 | K37: 0.63037634 | L37: 0.7311828 | M37: 1 | N37: 1 | O37: 1 | P37: 1 | Q37: MAJOR DOWNTIME
A38: 100153108217W509 | B38: OBE HVS 02-05-082-17W5 | C38: 70.8 | D38: 0.80593607 | E38: 0.047043011 | F38: 0.92857143 | G38: 0.10215054 | H38: 0.65138889 | I38: 0.97446237 | J38: 0.99305556 | K38: 1 | L38: 1 | M38: 1 | N38: 1 | O38: 1 | P38: 1 | Q38: MAJOR DOWNTIME
A39: 100023208319W509 | B39: OBE CADOTTE 02-05-084-19W5 | C39: 67.4 | D39: 0.81541096 | E39: 0.61827957 | F39: 0.69345238 | G39: 0.56317204 | H39: 0.775 | I39: 0.63709677 | J39: 0.68194444 | K39: 0.99865591 | L39: 0.8172043 | M39: 1 | N39: 0.99731183 | O39: 0.99722222 | P39: 1
A40: 102151908217W509 | B40: OBE HVS 03-19-082-17W5 | C40: 66 | D40: 0.81906393 | E40: 0.99596774 | F40: 0.96428571 | G40: 0.93951613 | H40: 0.95694444 | I40: 0.99462366 | J40: DOWN | K40: 1 | L40: 0.9811828 | M40: 1 | N40: DOWN | O40: 1 | P40: 1 | Q40: FULL SHUTDOWN
A41: 100160508317W509 | B41: OBE HVS 15-06-083-17W5 | C41: 63.7 | D41: 0.82557078 | E41: 0.096774194 | F41: 0.95535714 | G41: 0.91801075 | H41: 0.65833333 | I41: 0.61827957 | J41: 0.8375 | K41: 0.84139785 | L41: 1 | M41: 1 | N41: 1 | O41: 1 | P41: 1 | Q41: MAJOR DOWNTIME
...

Sheet Well Summary
A1: Obsidian Energy Ltd. — Peace River 2025 Production Summary
A2: Source: Alberta Energy Regulator Volumetric Data | All volumes in m³, oil rates in bbl/day
A4: Well Identifier | B4: Facility Name | C4: Location | D4: Type | E4: 2025 Oil (m³) | F4: 2025 Oil (bbl) | G4: 2025 Water (m³) | H4: 2025 Gas (e3m³) | I4: Prod Hours | J4: Uptime % | K4: Months Active | L4: Avg bbl/cal day | M4: Avg bbl/prod day
A5: 100021908317W509 | B5: OBE HVS 14-07-083-17W5 MWB | C5: 14-07-083-17W5 | D5: CRUDE BITUMEN MULTIWELL PRORATION BATTERY | E5: 12402.5 | F5: =E5*6.2898 -> 78009.245 | G5: 3200.8 | H5: 422 | I5: 5034 | J5: =I5/(365*24) -> 0.57465753 | K5: 8 | L5: =F5/365 -> 213.72396 | M5: =IF(I5>0,F5/(I5/24),0) -> 371.91535
A6: 100082908218W509 | B6: OBE HVS 08-28-082-18W5 | C6: 08-28-082-18W5 | D6: CRUDE BITUMEN MULTIWELL GROUP BATTERY | E6: 11988.8 | F6: =E6*6.2898 -> 75407.154 | G6: 4829.5 | H6: 2233.1 | I6: 8704 | J6: =I6/(365*24) -> 0.99360731 | K6: 12 | L6: =F6/365 -> 206.59494 | M6: =IF(I6>0,F6/(I6/24),0) -> 207.92414
A7: 102161808317W509 | B7: OBE HVS 13-08-083-17W5 | C7: 13-08-083-17W5 | D7: CRUDE BITUMEN MULTIWELL PRORATION BATTERY | E7: 11937 | F7: =E7*6.2898 -> 75081.343 | G7: 5351.9 | H7: 358.3 | I7: 6167 | J7: =I7/(365*24) -> 0.70399543 | K7: 9 | L7: =F7/365 -> 205.70231 | M7: =IF(I7>0,F7/(I7/24),0) -> 292.19267
A8: 100161508216W509 | B8: OBE WALRUS 07-21-082-16W5 | C8: 07-21-082-16W5 | D8: CRUDE BITUMEN MULTIWELL PRORATION BATTERY | E8: 11370.3 | F8: =E8*6.2898 -> 71516.913 | G8: 6762.3 | H8: 86.4 | I8: 5842 | J8: =I8/(365*24) -> 0.66689498 | K8: 8 | L8: =F8/365 -> 195.93675 | M8: =IF(I8>0,F8/(I8/24),0) -> 293.8045
A9: 102081807916W509 | B9: OBE PEAVINE 08-13-079-17W5 | C9: 13-079-17W5 | D9: CRUDE BITUMEN MULTIWELL PRORATION BATTERY | E9: 10387.5 | F9: =E9*6.2898 -> 65335.297 | G9: 2367.8 | H9: 155.7 | I9: 8753 | J9: =I9/(365*24) -> 0.99920091 | K9: 12 | L9: =F9/365 -> 179.00082 | M9: =IF(I9>0,F9/(I9/24),0) -> 179.14397
A10: 100141708317W509 | B10: OBE HVS 13-08-083-17W5 | C10: 13-08-083-17W5 | D10: CRUDE BITUMEN MULTIWELL PRORATION BATTERY | E10: 10347.3 | F10: =E10*6.2898 -> 65082.448 | G10: 1846.4 | H10: 1026.5 | I10: 8530 | J10: =I10/(365*24) -> 0.97374429 | K10: 12 | L10: =F10/365 -> 178.30808 | M10: =IF(I10>0,F10/(I10/24),0) -> 183.11591
A11: 100151908317W509 | B11: OBE HVS 13-18-083-17W5 | C11: 13-18-083-17W5 | D11: CRUDE BITUMEN MULTIWELL PRORATION BATTERY | E11: 9879.9 | F11: =E11*6.2898 -> 62142.595 | G11: 3746.2 | H11: 858.4 | I11: 8553 | J11: =I11/(365*24) -> 0.97636986 | K11: 12 | L11: =F11/365 -> 170.25368 | M11: =IF(I11>0,F11/(I11/24),0) -> 174.37417
A12: 102132307917W509 | B12: OBE DAWSON 04-23-079-17W5 | C12: 04-23-079-17W5 | D12: CRUDE BITUMEN MULTIWELL PRORATION BATTERY | E12: 9777.7 | F12: =E12*6.2898 -> 61499.777 | G12: 2093.1 | H12: 194.7 | I12: 6163 | J12: =I12/(365*24) -> 0.70353881 | K12: 9 | L12: =F12/365 -> 168.49254 | M12: =IF(I12>0,F12/(I12/24),0) -> 239.49289
A13: 102041207917W508 | B13: OBE DAWSON 13-13-079-17W5 | C13: 13-13-079-17W5 | D13: CRUDE BITUMEN MULTIWELL GROUP BATTERY | E13: 9685.6 | F13: =E13*6.2898 -> 60920.487 | G13: 1810.3 | H13: 747.9 | I13: 8682 | J13: =I13/(365*24) -> 0.99109589 | K13: 12 | L13: =F13/365 -> 166.90544 | M13: =IF(I13>0,F13/(I13/24),0) -> 168.40494
A14: 100131708317W509 | B14: OBE HVS 13-08-083-17W5 | C14: 13-08-083-17W5 | D14: CRUDE BITUMEN MULTIWELL PRORATION BATTERY | E14: 8941.5 | F14: =E14*6.2898 -> 56240.247 | G14: 3307 | H14: 295.3 | I14: 6128 | J14: =I14/(365*24) -> 0.69954338 | K14: 9 | L14: =F14/365 -> 154.08287 | M14: =IF(I14>0,F14/(I14/24),0) -> 220.26206
A15: 100051907916W509 | B15: OBE PEAVINE 08-13-079-17W5 | C15: 13-079-17W5 | D15: CRUDE BITUMEN MULTIWELL PRORATION BATTERY | E15: 8814.6 | F15: =E15*6.2898 -> 55442.071 | G15: 1465.3 | H15: 292.1 | I15: 8706 | J15: =I15/(365*24) -> 0.99383562 | K15: 12 | L15: =F15/365 -> 151.89609 | M15: =IF(I15>0,F15/(I15/24),0) -> 152.83824
A16: 100141808317W509 | B16: OBE HVS 14-07-083-17W5 MWB | C16: 14-07-083-17W5 | D16: CRUDE BITUMEN MULTIWELL PRORATION BATTERY | E16: 8480.2 | F16: =E16*6.2898 -> 53338.762 | G16: 4875.8 | H16: 601.1 | I16: 3476 | J16: =I16/(365*24) -> 0.39680365 | K16: 5 | L16: =F16/365 -> 146.13359 | M16: =IF(I16>0,F16/(I16/24),0) -> 368.27684
... A289: 100093108319W509 | B289: OBE CADOTTE 09-36-083-19W5 | C289: 36-083-20W5 | D289: CRUDE BITUMEN MULTIWELL PRORATION BATTERY | E289: 0.1 | F289: =E289*6.2898 -> 0.62898 | G289: 402.5 | H289: 168.7 | I289: 93 | J289: =I289/(365*24) -> 0.010616438 | K289: 1 | L289: =F289/365 -> 0.0017232329 | M289: =IF(I289>0,F289/(I289/24),0) -> 0.16231742
A290: TOTAL | E290: =SUM(E5:E289) -> 703831.5 | F290: =SUM(F5:F289) -> 4426959.4 | G290: =SUM(G5:G289) -> 691076 | H290: =SUM(H5:H289) -> 162288.2 | I290: =SUM(I5:I289) -> 2052174

Sheet Monthly Oil (m³)
A1: Monthly Oil Production (m³)
A3: Well Identifier | B3: Facility | C3: Jan | D3: Feb | E3: Mar | F3: Apr | G3: May | H3: Jun | I3: Jul | J3: Aug | K3: Sep | L3: Oct | M3: Nov | N3: Dec | O3: Total
A4: 100021908317W509 | B4: OBE HVS 14-07-083-17W5 MWB | G4: 1981.1 | H4: 2350.7 | I4: 232.9 | J4: 1930.5 | K4: 1584.5 | L4: 1481.9 | M4: 1500.1 | N4: 1340.8 | O4: =SUM(C4:N4) -> 12402.5
A5: 100082908218W509 | B5: OBE HVS 08-28-082-18W5 | C5: 1046.2 | D5: 1235.7 | E5: 1297.5 | F5: 1004.6 | G5: 1012.3 | H5: 1080.8 | I5: 1140 | J5: 1055.9 | K5: 968.2 | L5: 912.6 | M5: 558.1 | N5: 676.9 | O5: =SUM(C5:N5) -> 11988.8
A6: 102161808317W509 | B6: OBE HVS 13-08-083-17W5 | F6: 711.7 | G6: 2014.9 | H6: 1503.5 | I6: 1385 | J6: 1387.1 | K6: 1617.4 | L6: 1172.3 | M6: 1102.5 | N6: 1042.6 | O6: =SUM(C6:N6) -> 11937
A7: 100161508216W509 | B7: OBE WALRUS 07-21-082-16W5 | G7: 1783 | H7: 1809.6 | I7: 1472.5 | J7: 1476.6 | K7: 1247.1 | L7: 1189.2 | M7: 1057.1 | N7: 1335.2 | O7: =SUM(C7:N7) -> 11370.3
A8: 102081807916W509 | B8: OBE PEAVINE 08-13-079-17W5 | C8: 1308.6 | D8: 1111.4 | E8: 1042.7 | F8: 929.3 | G8: 900.1 | H8: 801.6 | I8: 836.7 | J8: 813.8 | K8: 731.3 | L8: 704.1 | M8: 623.2 | N8: 584.7 | O8: =SUM(C8:N8) -> 10387.5
A9: 100141708317W509 | B9: OBE HVS 13-08-083-17W5 | C9: 921.3 | D9: 987.4 | E9: 1083.2 | F9: 934.2 | G9: 1178.5 | H9: 745.5 | I9: 761.5 | J9: 829.5 | K9: 770.6 | L9: 752.4 | M9: 603 | N9: 780.2 | O9: =SUM(C9:N9) -> 10347.3
A10: 100151908317W509 | B10: OBE HVS 13-18-083-17W5 | C10: 1443.1 | D10: 988.2 | E10: 1390.3 | F10: 1156.5 | G10: 906.5 | H10: 576.2 | I10: 457.5 | J10: 519.1 | K10: 669.4 | L10: 622 | M10: 590.3 | N10: 560.8 | O10: =SUM(C10:N10) -> 9879.9
A11: 102132307917W509 | B11: OBE DAWSON 04-23-079-17W5 | F11: 651.3 | G11: 1917.5 | H11: 1642.6 | I11: 1483.7 | J11: 1130.3 | K11: 866.7 | L11: 806.5 | M11: 646.9 | N11: 632.2 | O11: =SUM(C11:N11) -> 9777.7
A12: 102041207917W508 | B12: OBE DAWSON 13-13-079-17W5 | C12: 1237.9 | D12: 920.8 | E12: 974.5 | F12: 891.7 | G12: 871.8 | H12: 930.4 | I12: 770.5 | J12: 719.1 | K12: 616 | L12: 641.5 | M12: 572.2 | N12: 539.2 | O12: =SUM(C12:N12) -> 9685.6
A13: 100131708317W509 | B13: OBE HVS 13-08-083-17W5 | F13: 873.5 | G13: 1397.3 | H13: 1443.3 | I13: 1186.7 | J13: 831.9 | K13: 734.2 | L13: 830.7 | M13: 833.4 | N13: 810.5 | O13: =SUM(C13:N13) -> 8941.5
A14: 100051907916W509 | B14: OBE PEAVINE 08-13-079-17W5 | C14: 1288.3 | D14: 972.8 | E14: 994.1 | F14: 888 | G14: 746.2 | H14: 746.5 | I14: 689.9 | J14: 595.4 | K14: 514 | L14: 487.5 | M14: 448.8 | N14: 443.1 | O14: =SUM(C14:N14) -> 8814.6
A15: 100141808317W509 | B15: OBE HVS 14-07-083-17W5 MWB | J15: 2274.8 | K15: 2145 | L15: 1624.4 | M15: 1341.9 | N15: 1094.1 | O15: =SUM(C15:N15) -> 8480.2
A16: 100062207917W509 | B16: OBE DAWSON 04-23-079-17W5 | E16: 522.9 | F16: 1383.5 | G16: 1293.5 | H16: 873.3 | I16: 984 | J16: 862.6 | K16: 667.4 | L16: 648.8 | M16: 562.7 | N16: 526.8 | O16: =SUM(C16:N16) -> 8325.5
A17: 100043208319W509 | B17: OBE CADOTTE 02-05-084-19W5 | C17: 961.1 | D17: 840.6 | E17: 652.5 | F17: 786.4 | G17: 772.4 | H17: 774 | I17: 698.9 | J17: 554.3 | K17: 582.6 | L17: 573.7 | M17: 547.4 | N17: 566.6 | O17: =SUM(C17:N17) -> 8310.5
A18: 102011207917W509 | B18: OBE DAWSON 07-13-079-17W5 | C18: 973.3 | D18: 883.9 | E18: 948.5 | F18: 857.2 | G18: 792.6 | H18: 704.9 | I18: 670.9 | J18: 621.2 | K18: 555.4 | L18: 532.7 | M18: 260.3 | N18: 295.8 | O18: =SUM(C18:N18) -> 8096.7
A19: 102041108114W509 | B19: OBE SEAL 04-14-081-14W5 MWB | E19: 104 | F19: 1222.6 | G19: 870 | H19: 646 | I19: 781.6 | J19: 1279.3 | K19: 949.8 | L19: 690.2 | M19: 713.4 | N19: 808.1 | O19: =SUM(C19:N19) -> 8065
A20: 102143008216W509 | B20: OBE WALRUS 13-19-082-16W5 | C20: 757.1 | D20: 648.2 | E20: 706.3 | F20: 619.7 | G20: 623.3 | H20: 627.2 | I20: 680.5 | J20: 663.7 | K20: 625.1 | L20: 657.5 | M20: 625 | N20: 622.3 | O20: =SUM(C20:N20) -> 7855.9
A21: 100052307917W509 | B21: OBE DAWSON 04-24-079-17W5 | G21: 1588.1 | H21: 1044.8 | I21: 1042.3 | J21: 1133.8 | K21: 850 | L21: 772 | M21: 706.2 | N21: 667.8 | O21: =SUM(C21:N21) -> 7805
A22: 100012207917W509 | B22: OBE DAWSON 04-24-079-17W5 | G22: 1650.9 | H22: 1311.1 | I22: 1092.1 | J22: 921 | K22: 707.9 | L22: 750.9 | M22: 680.6 | N22: 609.8 | O22: =SUM(C22:N22) -> 7724.3
A23: 103012708218W509 | B23: OBE HVS 08-28-082-18W5 | C23: 1156.3 | D23: 1010.5 | E23: 983.3 | F23: 746.6 | G23: 749.1 | H23: 622.9 | I23: 321.9 | J23: 422.8 | K23: 453.1 | L23: 462 | M23: 405.7 | N23: 317.4 | O23: =SUM(C23:N23) -> 7651.6
A24: 102082708218W509 | B24: OBE HVS 08-28-082-18W5 | C24: 1129.4 | D24: 918.4 | E24: 1026.2 | F24: 805.3 | G24: 582.1 | H24: 436.2 | I24: 446 | J24: 432.1 | K24: 363.1 | L24: 380.1 | M24: 431.5 | N24: 323.9 | O24: =SUM(C24:N24) -> 7274.3
A25: 100081807916W509 | B25: OBE PEAVINE 08-13-079-17W5 | C25: 1026.5 | D25: 781 | E25: 824.3 | F25: 698 | G25: 556.2 | H25: 524 | I25: 503.9 | J25: 502.8 | K25: 453.1 | L25: 445.7 | M25: 448.9 | N25: 435.6 | O25: =SUM(C25:N25) -> 7200
A26: 100053207917W508 | B26: OBE DAWSON 12-33-079-17W5 | C26: 870.1 | D26: 740 | E26: 764.5 | F26: 717 | G26: 727.8 | H26: 679.7 | I26: 671 | J26: 493.8 | K26: 295.5 | L26: 212.3 | M26: 435.2 | N26: 408.9 | O26: =SUM(C26:N26) -> 7015.8
A27: 100132908216W509 | B27: OBE WALRUS 06-20-082-16W5 | C27: 572.6 | D27: 679 | E27: 597.9 | F27: 461.9 | G27: 594.7 | H27: 522.2 | I27: 621.2 | J27: 557 | K27: 551.9 | L27: 581.9 | M27: 635.4 | N27: 600.5 | O27: =SUM(C27:N27) -> 6976.2
A28: 100061307917W509 | B28: OBE DAWSON 04-24-079-17W5 | J28: 1591 | K28: 1579.4 | L28: 1347.2 | M28: 1106.1 | N28: 984.1 | O28: =SUM(C28:N28) -> 6607.8
A29: 100013208319W509 | B29: OBE CADOTTE 02-05-084-19W5 | C29: 555.6 | D29: 564.3 | E29: 555.6 | F29: 472.8 | G29: 503.3 | H29: 566.8 | I29: 573 | J29: 540.4 | K29: 496.7 | L29: 488 | M29: 499.3 | N29: 481.8 | O29: =SUM(C29:N29) -> 6297.6
A30: 103151908217W509 | B30: OBE HVS 06-31-082-17W5 | C30: 586.1 | D30: 604.7 | E30: 639 | F30: 420.2 | G30: 584.3 | H30: 525.5 | I30: 552.6 | J30: 524.2 | K30: 489.2 | L30: 429 | M30: 433.2 | N30: 430.7 | O30: =SUM(C30:N30) -> 6218.7
A31: 100033208319W509 | B31: OBE CADOTTE 02-05-084-19W5 | C31: 506.6 | D31: 440.2 | E31: 520.5 | F31: 567.2 | G31: 598.1 | H31: 494.3 | I31: 404.9 | J31: 468.1 | K31: 524.8 | L31: 523.9 | M31: 476.3 | N31: 481.1 | O31: =SUM(C31:N31) -> 6006
A32: 102052307917W508 | B32: OBE DAWSON 04-24-079-17W5 | G32: 315.6 | H32: 1318.5 | I32: 1053.3 | J32: 936.8 | K32: 531.4 | L32: 572.4 | M32: 607.4 | N32: 561.6 | O32: =SUM(C32:N32) -> 5897
A33: 100090608316W509 | B33: OBE WALRUS 15-01-083-17W5 | C33: 326.6 | D33: 459.5 | E33: 936.6 | F33: 854 | G33: 478.2 | H33: 371.1 | I33: 495 | J33: 592.5 | K33: 441.4 | L33: 305.1 | M33: 282.2 | N33: 310 | O33: =SUM(C33:N33) -> 5852.2
A34: 102021207917W509 | B34: OBE DAWSON 07-13-079-17W5 | C34: 740.7 | D34: 613.9 | E34: 621.2 | F34: 560.9 | G34: 548.2 | H34: 533.1 | I34: 517.5 | J34: 487.5 | K34: 419.8 | L34: 402.6 | M34: 257 | N34: 144.2 | O34: =SUM(C34:N34) -> 5846.6
A35: 100092208019W508 | B35: OBE DAWSON 09-21-080-19W5 | C35: 906 | D35: 703.7 | E35: 680.2 | F35: 565.8 | G35: 524 | H35: 449.3 | I35: 416 | J35: 395.2 | K35: 335.7 | L35: 330.3 | M35: 186.3 | N35: 211.9 | O35: =SUM(C35:N35) -> 5704.4
A36: 102122807917W508 | B36: OBE DAWSON 05-27-079-17W5 MWPB | C36: 595.5 | D36: 560.5 | E36: 583.5 | F36: 569.5 | G36: 553.4 | H36: 512 | I36: 509.5 | J36: 473.2 | K36: 322.1 | L36: 260.2 | M36: 317 | N36: 340.9 | O36: =SUM(C36:N36) -> 5597.3
A37: 103153008216W509 | B37: OBE WALRUS 15-19-082-16W5 | C37: 476.1 | D37: 477 | E37: 479.4 | F37: 469.9 | G37: 501.5 | H37: 525.9 | I37: 526.3 | J37: 502.7 | K37: 388.9 | L37: 452.9 | M37: 398 | N37: 380.3 | O37: =SUM(C37:N37) -> 5578.9
A38: 100052807917W508 | B38: OBE DAWSON 05-27-079-17W5 MWPB | C38: 674.3 | D38: 532.3 | E38: 545.6 | F38: 567.9 | G38: 545.3 | H38: 503.4 | I38: 460.9 | J38: 471.6 | K38: 314 | L38: 259.4 | M38: 252.5 | N38: 364 | O38: =SUM(C38:N38) -> 5491.2
A39: 102082107917W509 | B39: OBE DAWSON 04-23-079-17W5 | E39: 370.8 | F39: 1021 | G39: 577.9 | H39: 570 | I39: 590.6 | J39: 566.9 | K39: 486.5 | L39: 458.7 | M39: 413.1 | N39: 421.4 | O39: =SUM(C39:N39) -> 5476.9
A40: 102141908317W509 | B40: OBE HVS 13-18-083-17W5 | F40: 247.2 | G40: 1195.1 | H40: 683.6 | I40: 725.4 | J40: 1113.1 | K40: 434.1 | L40: 378.1 | M40: 305.3 | N40: 385.5 | O40: =SUM(C40:N40) -> 5467.4
A41: 100122407917W508 | B41: OBE DAWSON 13-23-079-17W5 MWB | J41: 1344.2 | K41: 1259.9 | L41: 1016 | M41: 939.9 | N41: 819 | O41: =SUM(C41:N41) -> 5379
...

Sheet Monthly bbl per day
A1: Monthly Average Oil Rate (bbl/producing day)
A2: Rate = (Oil m³ x 6.2898) / (Production Hours / 24)
A4: Well Identifier | B4: Facility | C4: Jan | D4: Feb | E4: Mar | F4: Apr | G4: May | H4: Jun | I4: Jul | J4: Aug | K4: Sep | L4: Oct | M4: Nov | N4: Dec | O4: Total
A5: 100021908317W509 | B5: OBE HVS 14-07-083-17W5 MWB | G5: 451.1 | H5: 492.8 | I5: 366.2 | J5: 403.6 | K5: 341.2 | L5: 332.9 | M5: 314.5 | N5: 273.5 | O5: =IF('Well Summary'!I5>0,'Well Summary'!F5/('Well Summary'!I5/24),0) -> 371.91535
A6: 100082908218W509 | B6: OBE HVS 08-28-082-18W5 | C6: 216.3 | D6: 287.9 | E6: 264.7 | F6: 212.1 | G6: 205.4 | H6: 227.5 | I6: 231.9 | J6: 215.4 | K6: 203 | L6: 185.2 | M6: 117 | N6: 137.3 | O6: =IF('Well Summary'!I6>0,'Well Summary'!F6/('Well Summary'!I6/24),0) -> 207.92414
A7: 102161808317W509 | B7: OBE HVS 13-08-083-17W5 | F7: 265.9 | G7: 408.8 | H7: 315.2 | I7: 286 | J7: 320.2 | K7: 341.5 | L7: 239.8 | M7: 232.1 | N7: 211.5 | O7: =IF('Well Summary'!I7>0,'Well Summary'!F7/('Well Summary'!I7/24),0) -> 292.19267
A8: 100161508216W509 | B8: OBE WALRUS 07-21-082-16W5 | G8: 379.1 | H8: 379.4 | I8: 298.8 | J8: 299.6 | K8: 261.5 | L8: 241.3 | M8: 221.6 | N8: 272.4 | O8: =IF('Well Summary'!I8>0,'Well Summary'!F8/('Well Summary'!I8/24),0) -> 293.8045
A9: 102081807916W509 | B9: OBE PEAVINE 08-13-079-17W5 | C9: 265.5 | D9: 249.7 | E9: 211.6 | F9: 194.8 | G9: 183.6 | H9: 168.5 | I9: 170 | J9: 165.1 | K9: 153.3 | L9: 142.9 | M9: 130.7 | N9: 118.6 | O9: =IF('Well Summary'!I9>0,'Well Summary'!F9/('Well Summary'!I9/24),0) -> 179.14397
A10: 100141708317W509 | B10: OBE HVS 13-08-083-17W5 | C10: 222.9 | D10: 221.8 | E10: 220.4 | F10: 197 | G10: 239.1 | H10: 157.4 | I10: 154.5 | J10: 168.3 | K10: 161.6 | L10: 152.7 | M10: 146.6 | N10: 158.3 | O10: =IF('Well Summary'!I10>0,'Well Summary'!F10/('Well Summary'!I10/24),0) -> 183.11591
A11: 100151908317W509 | B11: OBE HVS 13-18-083-17W5 | C11: 292.8 | D11: 239.1 | E11: 302.4 | F11: 243.8 | G11: 183.9 | H11: 139.4 | I11: 93.1 | J11: 105.3 | K11: 140.3 | L11: 126.2 | M11: 125 | N11: 113.8 | O11: =IF('Well Summary'!I11>0,'Well Summary'!F11/('Well Summary'!I11/24),0) -> 174.37417
A12: 102132307917W509 | B12: OBE DAWSON 04-23-079-17W5 | F12: 302.5 | G12: 393.3 | H12: 359.4 | I12: 301 | J12: 229.3 | K12: 181.7 | L12: 163.6 | M12: 136.4 | N12: 128.3 | O12: =IF('Well Summary'!I12>0,'Well Summary'!F12/('Well Summary'!I12/24),0) -> 239.49289
A13: 102041207917W508 | B13: OBE DAWSON 13-13-079-17W5 | C13: 251.2 | D13: 216.5 | E13: 197.7 | F13: 187 | G13: 176.9 | H13: 195.1 | I13: 157.6 | J13: 145.9 | K13: 129.2 | L13: 130.2 | M13: 127.4 | N13: 109.4 | O13: =IF('Well Summary'!I13>0,'Well Summary'!F13/('Well Summary'!I13/24),0) -> 168.40494
A14: 100131708317W509 | B14: OBE HVS 13-08-083-17W5 | F14: 326.4 | G14: 283.5 | H14: 303.4 | I14: 240.8 | J14: 168.8 | K14: 190.1 | L14: 169.5 | M14: 177.9 | N14: 164.4 | O14: =IF('Well Summary'!I14>0,'Well Summary'!F14/('Well Summary'!I14/24),0) -> 220.26206
A15: 100051907916W509 | B15: OBE PEAVINE 08-13-079-17W5 | C15: 265.7 | D15: 218.5 | E15: 203.1 | F15: 186.2 | G15: 156 | H15: 156.9 | I15: 140.9 | J15: 122.1 | K15: 107.8 | L15: 98.9 | M15: 94.1 | N15: 89.9 | O15: =IF('Well Summary'!I15>0,'Well Summary'!F15/('Well Summary'!I15/24),0) -> 152.83824
A16: 100141808317W509 | B16: OBE HVS 14-07-083-17W5 MWB | J16: 462.2 | K16: 450.3 | L16: 330.5 | M16: 281.3 | N16: 299.2 | O16: =IF('Well Summary'!I16>0,'Well Summary'!F16/('Well Summary'!I16/24),0) -> 368.27684
A17: 100062207917W509 | B17: OBE DAWSON 04-23-079-17W5 | E17: 193.5 | F17: 308.9 | G17: 262.4 | H17: 220.5 | I17: 199.7 | J17: 175 | K17: 139.9 | L17: 131.6 | M17: 118 | N17: 106.9 | O17: =IF('Well Summary'!I17>0,'Well Summary'!F17/('Well Summary'!I17/24),0) -> 183.68569
A18: 100043208319W509 | B18: OBE CADOTTE 02-05-084-19W5 | C18: 195 | D18: 190.8 | E18: 153.4 | F18: 216.6 | G18: 206.4 | H18: 208.6 | I18: 142 | J18: 124.3 | K18: 122.1 | L18: 116.7 | M18: 115.1 | N18: 115 | O18: =IF('Well Summary'!I18>0,'Well Summary'!F18/('Well Summary'!I18/24),0) -> 155.56959
A19: 102011207917W509 | B19: OBE DAWSON 07-13-079-17W5 | C19: 197.5 | D19: 198.6 | E19: 192.4 | F19: 179.7 | G19: 160.8 | H19: 149.4 | I19: 136.1 | J19: 126 | K19: 116.4 | L19: 108.1 | M19: 71.2 | N19: 67.7 | O19: =IF('Well Summary'!I19>0,'Well Summary'!F19/('Well Summary'!I19/24),0) -> 143.79282
A20: 102041108114W509 | B20: OBE SEAL 04-14-081-14W5 MWB | E20: 23.6 | F20: 263.7 | G20: 183.9 | H20: 135.8 | I20: 159 | J20: 263.8 | K20: 202.8 | L20: 144.9 | M20: 154.5 | N20: 164 | O20: =IF('Well Summary'!I20>0,'Well Summary'!F20/('Well Summary'!I20/24),0) -> 170.58339
A21: 102143008216W509 | B21: OBE WALRUS 13-19-082-16W5 | C21: 155.7 | D21: 152.7 | E21: 147.7 | F21: 131.4 | G21: 130.3 | H21: 132.2 | I21: 138.1 | J21: 134.7 | K21: 131.1 | L21: 133.4 | M21: 132.3 | N21: 126.3 | O21: =IF('Well Summary'!I21>0,'Well Summary'!F21/('Well Summary'!I21/24),0) -> 137.00196
A22: 100052307917W509 | B22: OBE DAWSON 04-24-079-17W5 | G22: 322.2 | H22: 219.7 | I22: 211.5 | J22: 230 | K22: 178.7 | L22: 156.6 | M22: 148.1 | N22: 137.3 | O22: =IF('Well Summary'!I22>0,'Well Summary'!F22/('Well Summary'!I22/24),0) -> 200.85328
A23: 100012207917W509 | B23: OBE DAWSON 04-24-079-17W5 | G23: 335 | H23: 274.9 | I23: 221.6 | J23: 186.9 | K23: 148.8 | L23: 152.4 | M23: 142.7 | N23: 125.4 | O23: =IF('Well Summary'!I23>0,'Well Summary'!F23/('Well Summary'!I23/24),0) -> 198.7088
A24: 103012708218W509 | B24: OBE HVS 08-28-082-18W5 | C24: 234.9 | D24: 227.7 | E24: 199.5 | F24: 156.5 | G24: 152 | H24: 131.1 | I24: 71.1 | J24: 86.2 | K24: 95.5 | L24: 93.7 | M24: 85.1 | N24: 64.4 | O24: =IF('Well Summary'!I24>0,'Well Summary'!F24/('Well Summary'!I24/24),0) -> 132.99353
A25: 102082708218W509 | B25: OBE HVS 08-28-082-18W5 | C25: 231 | D25: 206.9 | E25: 208.2 | F25: 168.8 | G25: 131.2 | H25: 91.8 | I25: 90.5 | J25: 88.1 | K25: 76.6 | L25: 77.1 | M25: 90.5 | N25: 65.7 | O25: =IF('Well Summary'!I25>0,'Well Summary'!F25/('Well Summary'!I25/24),0) -> 126.69821
A26: 100081807916W509 | B26: OBE PEAVINE 08-13-079-17W5 | C26: 209.4 | D26: 175.4 | E26: 167.2 | F26: 146.3 | G26: 113.5 | H26: 110.2 | I26: 102.4 | J26: 102 | K26: 95 | L26: 90.4 | M26: 94.1 | N26: 90 | O26: =IF('Well Summary'!I26>0,'Well Summary'!F26/('Well Summary'!I26/24),0) -> 124.41363
A27: 100053207917W508 | B27: OBE DAWSON 12-33-079-17W5 | C27: 176.5 | D27: 169 | E27: 155.1 | F27: 152.9 | G27: 147.7 | H27: 142.5 | I27: 136.1 | J27: 100.2 | K27: 62 | L27: 64.6 | M27: 91.2 | N27: 83 | O27: =IF('Well Summary'!I27>0,'Well Summary'!F27/('Well Summary'!I27/24),0) -> 124.7581
A28: 100132908216W509 | B28: OBE WALRUS 06-20-082-16W5 | C28: 116.8 | D28: 152.5 | E28: 122.6 | F28: 96.8 | G28: 150.6 | H28: 129.4 | I28: 132.6 | J28: 114.4 | K28: 116 | L28: 118.1 | M28: 134 | N28: 128.4 | O28: =IF('Well Summary'!I28>0,'Well Summary'!F28/('Well Summary'!I28/24),0) -> 125.38322
A29: 100061307917W509 | B29: OBE DAWSON 04-24-079-17W5 | J29: 322.8 | K29: 331.1 | L29: 273.3 | M29: 231.9 | N29: 202.4 | O29: =IF('Well Summary'!I29>0,'Well Summary'!F29/('Well Summary'!I29/24),0) -> 272.38716
A30: 100013208319W509 | B30: OBE CADOTTE 02-05-084-19W5 | C30: 112.9 | D30: 142.4 | E30: 112.7 | F30: 107.2 | G30: 130.1 | H30: 152.2 | I30: 116.4 | J30: 118.6 | K30: 104.1 | L30: 100.9 | M30: 105 | N30: 98.6 | O30: =IF('Well Summary'!I30>0,'Well Summary'!F30/('Well Summary'!I30/24),0) -> 115.45488
A31: 103151908217W509 | B31: OBE HVS 06-31-082-17W5 | C31: 118.9 | D31: 135.8 | E31: 129.7 | F31: 88.1 | G31: 118.6 | H31: 110.2 | I31: 112.1 | J31: 106.9 | K31: 102.6 | L31: 87 | M31: 90.8 | N31: 87.4 | O31: =IF('Well Summary'!I31>0,'Well Summary'!F31/('Well Summary'!I31/24),0) -> 107.21164
A32: 100033208319W509 | B32: OBE CADOTTE 02-05-084-19W5 | C32: 102.8 | D32: 99.2 | E32: 157.5 | F32: 154.8 | G32: 182.4 | H32: 140.3 | I32: 82.3 | J32: 102 | K32: 110 | L32: 107.9 | M32: 100.1 | N32: 97.6 | O32: =IF('Well Summary'!I32>0,'Well Summary'!F32/('Well Summary'!I32/24),0) -> 115.58349
A33: 102052307917W508 | B33: OBE DAWSON 04-24-079-17W5 | G33: 141.8 | H33: 276.4 | I33: 215.4 | J33: 190.1 | K33: 111.4 | L33: 116.1 | M33: 127.3 | N33: 115.5 | O33: =IF('Well Summary'!I33>0,'Well Summary'!F33/('Well Summary'!I33/24),0) -> 163.15667
A34: 100090608316W509 | B34: OBE WALRUS 15-01-083-17W5 | C34: 115.2 | D34: 140.1 | E34: 191.1 | F34: 179 | G34: 102 | H34: 78.2 | I34: 100.7 | J34: 120.2 | K34: 96 | L34: 62.3 | M34: 59.2 | N34: 62.9 | O34: =IF('Well Summary'!I34>0,'Well Summary'!F34/('Well Summary'!I34/24),0) -> 107.86569
A35: 102021207917W509 | B35: OBE DAWSON 07-13-079-17W5 | C35: 150.3 | D35: 137.9 | E35: 126 | F35: 117.6 | G35: 111.2 | H35: 111.8 | I35: 105 | J35: 98.9 | K35: 88 | L35: 81.7 | M35: 53.9 | N35: 29.5 | O35: =IF('Well Summary'!I35>0,'Well Summary'!F35/('Well Summary'!I35/24),0) -> 100.80807
A36: 100092208019W508 | B36: OBE DAWSON 09-21-080-19W5 | C36: 183.8 | D36: 158.5 | E36: 138 | F36: 119.3 | G36: 106.3 | H36: 94.7 | I36: 84.4 | J36: 81.1 | K36: 70.4 | L36: 67 | M36: 39.1 | N36: 43 | O36: =IF('Well Summary'!I36>0,'Well Summary'!F36/('Well Summary'!I36/24),0) -> 98.502499
A37: 102122807917W508 | B37: OBE DAWSON 05-27-079-17W5 MWPB | C37: 120.8 | D37: 125.9 | E37: 118.4 | F37: 119.4 | G37: 112.3 | H37: 107.3 | I37: 103.4 | J37: 96 | K37: 92.4 | L37: 79.2 | M37: 66.5 | N37: 69.2 | O37: =IF('Well Summary'!I37>0,'Well Summary'!F37/('Well Summary'!I37/24),0) -> 101.57989
A38: 103153008216W509 | B38: OBE WALRUS 15-19-082-16W5 | C38: 98.5 | D38: 107.2 | E38: 98.3 | F38: 98.5 | G38: 101.8 | H38: 110.3 | I38: 106.8 | J38: 102.3 | K38: 81.5 | L38: 91.9 | M38: 83.4 | N38: 77.2 | O38: =IF('Well Summary'!I38>0,'Well Summary'!F38/('Well Summary'!I38/24),0) -> 96.401553
A39: 100052807917W508 | B39: OBE DAWSON 05-27-079-17W5 MWPB | C39: 136.8 | D39: 119.6 | E39: 110.7 | F39: 119.9 | G39: 110.8 | H39: 106.7 | I39: 93.5 | J39: 95.7 | K39: 90.1 | L39: 78.5 | M39: 64.8 | N39: 73.9 | O39: =IF('Well Summary'!I39>0,'Well Summary'!F39/('Well Summary'!I39/24),0) -> 101.39758
A40: 102082107917W509 | B40: OBE DAWSON 04-23-079-17W5 | E40: 137.2 | F40: 214.1 | G40: 117.9 | H40: 119.5 | I40: 119.8 | J40: 115 | K40: 102 | L40: 93.1 | M40: 86.6 | N40: 85.5 | O40: =IF('Well Summary'!I40>0,'Well Summary'!F40/('Well Summary'!I40/24),0) -> 118.04205
A41: 102141908317W509 | B41: OBE HVS 13-18-083-17W5 | F41: 91.5 | G41: 242.5 | H41: 145.1 | I41: 147.6 | J41: 244.9 | K41: 94.2 | L41: 77.1 | M41: 64 | N41: 78.2 | O41: =IF('Well Summary'!I41>0,'Well Summary'!F41/('Well Summary'!I41/24),0) -> 133.31166
...

Sheet Monthly Hours
A1: Monthly Production Hours by Well
A3: Well Identifier | B3: Facility | C3: Jan (max 744) | D3: Feb (max 672) | E3: Mar (max 744) | F3: Apr (max 720) | G3: May (max 744) | H3: Jun (max 720) | I3: Jul (max 744) | J3: Aug (max 744) | K3: Sep (max 720) | L3: Oct (max 744) | M3: Nov (max 720) | N3: Dec (max 744) | O3: Total
A4: 100021908317W509 | B4: OBE HVS 14-07-083-17W5 MWB | G4: 663 | H4: 720 | I4: 96 | J4: 722 | K4: 701 | L4: 672 | M4: 720 | N4: 740 | O4: =SUM(C4:N4) -> 5034
A5: 100082908218W509 | B5: OBE HVS 08-28-082-18W5 | C5: 730 | D5: 648 | E5: 740 | F5: 715 | G5: 744 | H5: 717 | I5: 742 | J5: 740 | K5: 720 | L5: 744 | M5: 720 | N5: 744 | O5: =SUM(C5:N5) -> 8704
A6: 102161808317W509 | B6: OBE HVS 13-08-083-17W5 | F6: 404 | G6: 744 | H6: 720 | I6: 731 | J6: 654 | K6: 715 | L6: 738 | M6: 717 | N6: 744 | O6: =SUM(C6:N6) -> 6167
A7: 100161508216W509 | B7: OBE WALRUS 07-21-082-16W5 | G7: 710 | H7: 720 | I7: 744 | J7: 744 | K7: 720 | L7: 744 | M7: 720 | N7: 740 | O7: =SUM(C7:N7) -> 5842
A8: 102081807916W509 | B8: OBE PEAVINE 08-13-079-17W5 | C8: 744 | D8: 672 | E8: 744 | F8: 720 | G8: 740 | H8: 718 | I8: 743 | J8: 744 | K8: 720 | L8: 744 | M8: 720 | N8: 744 | O8: =SUM(C8:N8) -> 8753
A9: 100141708317W509 | B9: OBE HVS 13-08-083-17W5 | C9: 624 | D9: 672 | E9: 742 | F9: 716 | G9: 744 | H9: 715 | I9: 744 | J9: 744 | K9: 720 | L9: 744 | M9: 621 | N9: 744 | O9: =SUM(C9:N9) -> 8530
A10: 100151908317W509 | B10: OBE HVS 13-18-083-17W5 | C10: 744 | D10: 624 | E10: 694 | F10: 716 | G10: 744 | H10: 624 | I10: 742 | J10: 744 | K10: 720 | L10: 744 | M10: 713 | N10: 744 | O10: =SUM(C10:N10) -> 8553
A11: 102132307917W509 | B11: OBE DAWSON 04-23-079-17W5 | F11: 325 | G11: 736 | H11: 690 | I11: 744 | J11: 744 | K11: 720 | L11: 744 | M11: 716 | N11: 744 | O11: =SUM(C11:N11) -> 6163
A12: 102041207917W508 | B12: OBE DAWSON 13-13-079-17W5 | C12: 744 | D12: 642 | E12: 744 | F12: 720 | G12: 744 | H12: 720 | I12: 738 | J12: 744 | K12: 720 | L12: 744 | M12: 678 | N12: 744 | O12: =SUM(C12:N12) -> 8682
A13: 100131708317W509 | B13: OBE HVS 13-08-083-17W5 | F13: 404 | G13: 744 | H13: 718 | I13: 744 | J13: 744 | K13: 583 | L13: 740 | M13: 707 | N13: 744 | O13: =SUM(C13:N13) -> 6128
A14: 100051907916W509 | B14: OBE PEAVINE 08-13-079-17W5 | C14: 732 | D14: 672 | E14: 739 | F14: 720 | G14: 722 | H14: 718 | I14: 739 | J14: 736 | K14: 720 | L14: 744 | M14: 720 | N14: 744 | O14: =SUM(C14:N14) -> 8706
A15: 100141808317W509 | B15: OBE HVS 14-07-083-17W5 MWB | J15: 743 | K15: 719 | L15: 742 | M15: 720 | N15: 552 | O15: =SUM(C15:N15) -> 3476
A16: 100062207917W509 | B16: OBE DAWSON 04-23-079-17W5 | E16: 408 | F16: 676 | G16: 744 | H16: 598 | I16: 744 | J16: 744 | K16: 720 | L16: 744 | M16: 720 | N16: 744 | O16: =SUM(C16:N16) -> 6842
A17: 100043208319W509 | B17: OBE CADOTTE 02-05-084-19W5 | C17: 744 | D17: 665 | E17: 642 | F17: 548 | G17: 565 | H17: 560 | I17: 743 | J17: 673 | K17: 720 | L17: 742 | M17: 718 | N17: 744 | O17: =SUM(C17:N17) -> 8064
A18: 102011207917W509 | B18: OBE DAWSON 07-13-079-17W5 | C18: 744 | D18: 672 | E18: 744 | F18: 720 | G18: 744 | H18: 712 | I18: 744 | J18: 744 | K18: 720 | L18: 744 | M18: 552 | N18: 660 | O18: =SUM(C18:N18) -> 8500
A19: 102041108114W509 | B19: OBE SEAL 04-14-081-14W5 MWB | E19: 664 | F19: 700 | G19: 714 | H19: 718 | I19: 742 | J19: 732 | K19: 707 | L19: 719 | M19: 697 | N19: 744 | O19: =SUM(C19:N19) -> 7137
A20: 102143008216W509 | B20: OBE WALRUS 13-19-082-16W5 | C20: 734 | D20: 641 | E20: 722 | F20: 712 | G20: 722 | H20: 716 | I20: 744 | J20: 744 | K20: 720 | L20: 744 | M20: 713 | N20: 744 | O20: =SUM(C20:N20) -> 8656
A21: 100052307917W509 | B21: OBE DAWSON 04-24-079-17W5 | G21: 744 | H21: 718 | I21: 744 | J21: 744 | K21: 718 | L21: 744 | M21: 720 | N21: 734 | O21: =SUM(C21:N21) -> 5866
A22: 100012207917W509 | B22: OBE DAWSON 04-24-079-17W5 | G22: 744 | H22: 720 | I22: 744 | J22: 744 | K22: 718 | L22: 744 | M22: 720 | N22: 734 | O22: =SUM(C22:N22) -> 5868
A23: 103012708218W509 | B23: OBE HVS 08-28-082-18W5 | C23: 743 | D23: 670 | E23: 744 | F23: 720 | G23: 744 | H23: 717 | I23: 683 | J23: 740 | K23: 716 | L23: 744 | M23: 720 | N23: 744 | O23: =SUM(C23:N23) -> 8685
A24: 102082708218W509 | B24: OBE HVS 08-28-082-18W5 | C24: 738 | D24: 670 | E24: 744 | F24: 720 | G24: 670 | H24: 717 | I24: 744 | J24: 740 | K24: 716 | L24: 744 | M24: 720 | N24: 744 | O24: =SUM(C24:N24) -> 8667
A25: 100081807916W509 | B25: OBE PEAVINE 08-13-079-17W5 | C25: 740 | D25: 672 | E25: 744 | F25: 720 | G25: 740 | H25: 718 | I25: 743 | J25: 744 | K25: 720 | L25: 744 | M25: 720 | N25: 731 | O25: =SUM(C25:N25) -> 8736
A26: 100053207917W508 | B26: OBE DAWSON 12-33-079-17W5 | C26: 744 | D26: 661 | E26: 744 | F26: 708 | G26: 744 | H26: 720 | I26: 744 | J26: 744 | K26: 720 | L26: 496 | M26: 720 | N26: 744 | O26: =SUM(C26:N26) -> 8489
A27: 100132908216W509 | B27: OBE WALRUS 06-20-082-16W5 | C27: 740 | D27: 672 | E27: 736 | F27: 720 | G27: 596 | H27: 609 | I27: 707 | J27: 735 | K27: 718 | L27: 744 | M27: 716 | N27: 706 | O27: =SUM(C27:N27) -> 8399
A28: 100061307917W509 | B28: OBE DAWSON 04-24-079-17W5 | J28: 744 | K28: 720 | L28: 744 | M28: 720 | N28: 734 | O28: =SUM(C28:N28) -> 3662
A29: 100013208319W509 | B29: OBE CADOTTE 02-05-084-19W5 | C29: 743 | D29: 598 | E29: 744 | F29: 666 | G29: 584 | H29: 562 | I29: 743 | J29: 688 | K29: 720 | L29: 730 | M29: 718 | N29: 738 | O29: =SUM(C29:N29) -> 8234
A30: 103151908217W509 | B30: OBE HVS 06-31-082-17W5 | C30: 744 | D30: 672 | E30: 744 | F30: 720 | G30: 744 | H30: 720 | I30: 744 | J30: 740 | K30: 720 | L30: 744 | M30: 720 | N30: 744 | O30: =SUM(C30:N30) -> 8756
A31: 100033208319W509 | B31: OBE CADOTTE 02-05-084-19W5 | C31: 744 | D31: 670 | E31: 499 | F31: 553 | G31: 495 | H31: 532 | I31: 743 | J31: 693 | K31: 720 | L31: 733 | M31: 718 | N31: 744 | O31: =SUM(C31:N31) -> 7844
A32: 102052307917W508 | B32: OBE DAWSON 04-24-079-17W5 | G32: 336 | H32: 720 | I32: 738 | J32: 744 | K32: 720 | L32: 744 | M32: 720 | N32: 734 | O32: =SUM(C32:N32) -> 5456
A33: 100090608316W509 | B33: OBE WALRUS 15-01-083-17W5 | C33: 428 | D33: 495 | E33: 740 | F33: 720 | G33: 708 | H33: 716 | I33: 742 | J33: 744 | K33: 694 | L33: 739 | M33: 720 | N33: 744 | O33: =SUM(C33:N33) -> 8190
A34: 102021207917W509 | B34: OBE DAWSON 07-13-079-17W5 | C34: 744 | D34: 672 | E34: 744 | F34: 720 | G34: 744 | H34: 720 | I34: 744 | J34: 744 | K34: 720 | L34: 744 | M34: 720 | N34: 739 | O34: =SUM(C34:N34) -> 8755
A35: 100092208019W508 | B35: OBE DAWSON 09-21-080-19W5 | C35: 744 | D35: 670 | E35: 744 | F35: 716 | G35: 744 | H35: 716 | I35: 744 | J35: 736 | K35: 720 | L35: 744 | M35: 720 | N35: 744 | O35: =SUM(C35:N35) -> 8742
A36: 102122807917W508 | B36: OBE DAWSON 05-27-079-17W5 MWPB | C36: 744 | D36: 672 | E36: 744 | F36: 720 | G36: 744 | H36: 720 | I36: 744 | J36: 744 | K36: 526 | L36: 496 | M36: 720 | N36: 744 | O36: =SUM(C36:N36) -> 8318
A37: 103153008216W509 | B37: OBE WALRUS 15-19-082-16W5 | C37: 730 | D37: 672 | E37: 736 | F37: 720 | G37: 744 | H37: 720 | I37: 744 | J37: 742 | K37: 720 | L37: 744 | M37: 720 | N37: 744 | O37: =SUM(C37:N37) -> 8736
A38: 100052807917W508 | B38: OBE DAWSON 05-27-079-17W5 MWPB | C38: 744 | D38: 672 | E38: 744 | F38: 715 | G38: 743 | H38: 712 | I38: 744 | J38: 744 | K38: 526 | L38: 499 | M38: 588 | N38: 744 | O38: =SUM(C38:N38) -> 8175
A39: 102082107917W509 | B39: OBE DAWSON 04-23-079-17W5 | E39: 408 | F39: 720 | G39: 740 | H39: 720 | I39: 744 | J39: 744 | K39: 720 | L39: 744 | M39: 720 | N39: 744 | O39: =SUM(C39:N39) -> 7004
A40: 102141908317W509 | B40: OBE HVS 13-18-083-17W5 | F40: 408 | G40: 744 | H40: 711 | I40: 742 | J40: 686 | K40: 696 | L40: 740 | M40: 720 | N40: 744 | O40: =SUM(C40:N40) -> 6191
A41: 100122407917W508 | B41: OBE DAWSON 13-23-079-17W5 MWB | J41: 696 | K41: 718 | L41: 744 | M41: 720 | N41: 744 | O41: =SUM(C41:N41) -> 3622
...

Sheet Top 50 Producers
A1: Top 50 Oil Producing Wells — Peace River 2025
A3: Rank | B3: Well Identifier | C3: Facility Name | D3: Location | E3: 2025 Oil (bbl) | F3: Prod Hours | G3: Uptime % | H3: Avg bbl/cal day | I3: Avg bbl/prod day
A4: 1 | B4: 100021908317W509 | C4: OBE HVS 14-07-083-17W5 MWB | D4: 14-07-083-17W5 | E4: 78009 | F4: 5034 | G4: =F4/(365*24) -> 0.57465753 | H4: =E4/365 -> 213.72329 | I4: =IF(F4>0,E4/(F4/24),0) -> 371.91418
A5: 2 | B5: 100082908218W509 | C5: OBE HVS 08-28-082-18W5 | D5: 08-28-082-18W5 | E5: 75407 | F5: 8704 | G5: =F5/(365*24) -> 0.99360731 | H5: =E5/365 -> 206.59452 | I5: =IF(F5>0,E5/(F5/24),0) -> 207.92371
A6: 3 | B6: 102161808317W509 | C6: OBE HVS 13-08-083-17W5 | D6: 13-08-083-17W5 | E6: 75081 | F6: 6167 | G6: =F6/(365*24) -> 0.70399543 | H6: =E6/365 -> 205.70137 | I6: =IF(F6>0,E6/(F6/24),0) -> 292.19134
A7: 4 | B7: 100161508216W509 | C7: OBE WALRUS 07-21-082-16W5 | D7: 07-21-082-16W5 | E7: 71517 | F7: 5842 | G7: =F7/(365*24) -> 0.66689498 | H7: =E7/365 -> 195.93699 | I7: =IF(F7>0,E7/(F7/24),0) -> 293.80486
A8: 5 | B8: 102081807916W509 | C8: OBE PEAVINE 08-13-079-17W5 | D8: 13-079-17W5 | E8: 65335 | F8: 8753 | G8: =F8/(365*24) -> 0.99920091 | H8: =E8/365 -> 179 | I8: =IF(F8>0,E8/(F8/24),0) -> 179.14315
A9: 6 | B9: 100141708317W509 | C9: OBE HVS 13-08-083-17W5 | D9: 13-08-083-17W5 | E9: 65082 | F9: 8530 | G9: =F9/(365*24) -> 0.97374429 | H9: =E9/365 -> 178.30685 | I9: =IF(F9>0,E9/(F9/24),0) -> 183.11465
A10: 7 | B10: 100151908317W509 | C10: OBE HVS 13-18-083-17W5 | D10: 13-18-083-17W5 | E10: 62143 | F10: 8553 | G10: =F10/(365*24) -> 0.97636986 | H10: =E10/365 -> 170.25479 | I10: =IF(F10>0,E10/(F10/24),0) -> 174.37531
A11: 8 | B11: 102132307917W509 | C11: OBE DAWSON 04-23-079-17W5 | D11: 04-23-079-17W5 | E11: 61500 | F11: 6163 | G11: =F11/(365*24) -> 0.70353881 | H11: =E11/365 -> 168.49315 | I11: =IF(F11>0,E11/(F11/24),0) -> 239.49375
A12: 9 | B12: 102041207917W508 | C12: OBE DAWSON 13-13-079-17W5 | D12: 13-13-079-17W5 | E12: 60920 | F12: 8682 | G12: =F12/(365*24) -> 0.99109589 | H12: =E12/365 -> 166.90411 | I12: =IF(F12>0,E12/(F12/24),0) -> 168.40359
A13: 10 | B13: 100131708317W509 | C13: OBE HVS 13-08-083-17W5 | D13: 13-08-083-17W5 | E13: 56240 | F13: 6128 | G13: =F13/(365*24) -> 0.69954338 | H13: =E13/365 -> 154.08219 | I13: =IF(F13>0,E13/(F13/24),0) -> 220.2611
A14: 11 | B14: 100051907916W509 | C14: OBE PEAVINE 08-13-079-17W5 | D14: 13-079-17W5 | E14: 55442 | F14: 8706 | G14: =F14/(365*24) -> 0.99383562 | H14: =E14/365 -> 151.89589 | I14: =IF(F14>0,E14/(F14/24),0) -> 152.83804
A15: 12 | B15: 100141808317W509 | C15: OBE HVS 14-07-083-17W5 MWB | D15: 14-07-083-17W5 | E15: 53339 | F15: 3476 | G15: =F15/(365*24) -> 0.39680365 | H15: =E15/365 -> 146.13425 | I15: =IF(F15>0,E15/(F15/24),0) -> 368.27848
... A53: 50 | B53: 102092107917W509 | C53: OBE DAWSON 13-23-079-17W5 MWB | D53: 13-23-079-17W5 | E53: 30298 | F53: 3001 | G53: =F53/(365*24) -> 0.34257991 | H53: =E53/365 -> 83.008219 | I53: =IF(F53>0,E53/(F53/24),0) -> 242.30323
